Workbook

Sheet readme
A1: Tabs 1-9 are used for this paper:
A3: As large as microscopic life: A comprehensive guide to accurate estimates of body mass and allometric scaling for the aquatic micro-world
A5: Julia Reiss1*, Andrea Perna2, and Daniel Perkins1
A7: 1 Brunel University London, College of Health, Medicine and Life Sciences, Division of Environmental Sciences, Brunel University London, Uxbridge, UB8 3PH, UK.
A8: 2 IMT School for Advanced Studies Lucca, Piazza S. Francesco, 19 - 55100 Lucca, Italy
A9: * corresponding author Email: julia.reiss@brunel.ac.uk (JR)
A11: The tab number correspondes to the number for supplementary information.
A12: Tabs 1,2,3,4 and 7 feature in shorter form in the main MS.
A14: Tabs 1, 2 and 3 are background for estimating body mass
A17: Tabs 4 and 5 are methods to compare body mass estimates
B18: calculate body weight from dimensions by entering measuremtns and selecting the best geometric shape and conversion factors
B19: taxa specific equations are available. In the tab they are compared to each other and the volume and weight of a simple geometric shape
A26: Tabs 6&7 explain temperature corrections for metabolic rate and related rates after gillooly and with Q10
A29: figure 1 is background
A30: glossary is for all terms used in manuscript
A32: figure 2 has dummy data to show the slope of the allometric relationship
B33: viruses not include as black box regarding these parametres
B34: Data for expected abundaunce (N) are the perpendicular line of metabolci rate (W) - this line will have a slope with the opposite reciprocal. In simpler terms, you flip the slope and change the sign.
AA48: Katrin Layer data unpubl.

Sheet 1a
A1: Background | B1: literature average body sizes | C1: Size group | D1: Size group name | E1: Group | F1: Example | G1: L (µm) | H1: V (µm3), i.e. V (fL) | I1: V (nl) | J1: FW (µg) | K1: DW (µg) | L1: µgC/ind. | M1: L (mm) | N1: V (ml) | O1: FW (mg) | P1: DW (mg) min | Q1: FW(g) | R1: DW (g) | S1: L (m) | T1: gC/ind. | U1: Reference | V1: raw data as given by authors for length | W1: raw data as given by authors | X1: comment 1 | Y1: comment 2
C2: 5 | D2: Viruses | E2: Viruses | T2: =0.2*POWER(10,-15) -> 2e-16 | U2: Wilhelm and Suttle 1999 | W2: 0.2 fgC
C3: 5 | D3: Viruses | E3: Viruses | F3: marine virus | T3: =0.055*POWER(10,-15) -> 5.5e-17 | U3: Steward et al. 2007 | W3: 0.055fgC
C4: 5 | D4: Viruses | E4: Viruses | F4: virus small | G4: =16/1000 -> 0.016 | S4: =G4*POWER(10,-6) -> 1.6e-08 | U4: Modrow et al. 2013 | V4: 16 nm
C5: 5 | D5: Viruses | E5: Viruses | F5: virus small | G5: 0.017 | S5: =G5*POWER(10,-6) -> 1.7e-08 | U5: Sevvana et al. 2021 | W5: Angstrom
C6: 5 | D6: Viruses | E6: Viruses | F6: Bacteriophage typical | G6: =50/1000 -> 0.05 | L6: =T6*1000000 -> 2e-11 | M6: =G6/1000 -> 5e-05 | S6: =G6*POWER(10,-6) -> 5e-08 | T6: =0.02*POWER(10,-15) -> 2e-17 | U6: Bar-On et al. 2018 | W6: ≈0.02 fg C, 50nm length
C7: 5 | D7: Viruses | E7: Viruses | F7: SARS-CoV-2 virus | G7: 0.1 | L7: =T7*1000000 -> 1e-09 | M7: =G7/1000 -> 0.0001 | S7: =G7*POWER(10,-6) -> 1e-07 | T7: 1e-15 | U7: Bar-On et al. 2020 | W7: 1fg, 100nm in diamtre
C8: 5 | D8: Viruses | E8: Viruses | F8: Bacteriophage Lambda | G8: =180/1000 -> 0.18 | S8: =G8*POWER(10,-6) -> 1.8e-07 | T8: =58*POWER(10,6)*1.66054*POWER(10,-24) -> 9.631132e-17 | U8: Hohn & Katsura 1977 | W8: 58 x 106 daltons | X8: head with a radius of 30 nm and a flexible tail 150 nm long
C9: 5 | D9: Viruses | E9: Viruses | F9: Bacteriophage T2 | G9: =195/1000 -> 0.195 | S9: =G9*POWER(10,-6) -> 1.95e-07 | T9: =325*POWER(10,6)*1.66054*POWER(10,-24) -> 5.396755e-16 | U9: Matthews 1975 | W9: 325 x 106 dalton; 34.6 × 104nm3 | X9: 1 dalton = 1.66054E-24g
C10: 5 | D10: Viruses | E10: Viruses | F10: virus large | G10: =300/1000 -> 0.3 | S10: =G10*POWER(10,-6) -> 3e-07 | U10: Modrow et al. 2013 | V10: 300 nm
C11: 5 | D11: Viruses | E11: Viruses | F11: Mimivirus that infects protozoa | G11: =400/1000 -> 0.4 | S11: =G11*POWER(10,-6) -> 4e-07 | U11: Dimmock et al. 2015
C12: 5 | D12: Viruses | E12: Viruses | F12: phage of Autographa californica | J12: =Q12*1000000 -> 1e-09 | Q12: 1e-15 | U12: Ilic et al. 2004 | W12: 1 fg
C13: 5 | D13: Viruses | E13: Viruses | F13: Bacteriophage | G13: =82/1000 -> 0.082 | R13: =99*POWER(10,6)/1.6605*POWER(10,-24) -> 5.9620596e-17 | S13: =G13*POWER(10,-6) -> 8.2e-08 | U13: Day and Mindich 1980 | V13: 82 nm | W13: molecular weight of 99 × 106
C14: 4 | D14: Bacteria | E14: Bacteria - heterotroph | F14: SAR11 marine clade | G14: =M14*1000 -> 0.12 | M14: =0.000012*10 -> 0.00012 | S14: =G14*POWER(10,-6) -> 1.2e-07 | U14: Andersen et al. 2015 | W14: cm
C15: 4 | D15: Bacteria | E15: Bacteria | S15: =0.15/1000/1000 -> 1.5e-07 | U15: Hatton et al. 2021 | V15: smallest cell 0.15 μm
C16: 4 | D16: Bacteria | E16: Bacteria - general | F16: Aquatic bacterium | G16: ~0.72 | H16: 0.2 | L16: na | M16: =0.2/1000 -> 0.0002 | S16: na | T16: =20*0.000000000000001 -> 2e-14 | U16: Findlay et al. 2002 | W16: 0.2μm3
C17: 4 | D17: Bacteria | E17: Bacteria | F17: small | S17: =0.2*POWER(10,-6) -> 2e-07 | U17: Schulz & Jørgensen 2001 | V17: 0.2 microm
C18: 4 | D18: Bacteria | E18: Bacteria - autotroph | F18: Prochlorococcus sp. | G18: =M18*1000 -> 0.5 | M18: =0.00005*10 -> 0.0005 | S18: =G18*POWER(10,-6) -> 5e-07 | U18: Bar-On et al. 2018 | W18: cm
C19: 4 | D19: Bacteria | E19: Bacteria - autotroph | F19: Chroococcus sp. | G19: =M19*1000 -> 25 | M19: =0.0025*10 -> 0.025 | S19: =G19*POWER(10,-6) -> 2.5e-05 | U19: Bar-On et al. 2018 | W19: cm
C20: 4 | D20: Bacteria | E20: Bacteria | F20: Achromatium oxaliferum, the largest free living single-celled prokaryotes | G20: 95 | H20: 80000 | I20: =H20/1000000 -> 0.08 | N20: =I20/1000 -> 8e-05 | S20: =95*POWER(10,-6) -> 9.5e-05 | U20: Schulz & Jørgensen 2001 | V20: 95 microm | W20: biovolume in microm3
C21: 4 | D21: Bacteria | E21: Bacteria - heterotroph | F21: E. coli | L21: =T21*1000000 -> 1.5e-07 | T21: =150*POWER(10,-15) -> 1.5e-13 | U21: Bar-On et al. 2018 | W21: ≈150 fg C
C22: 4 | D22: Bacteria | E22: Bacteria - heterotroph | F22: marine, brakish and freshwater bacteria | H22: 6 | I22: =H22/1000000 -> 6e-06 | N22: =I22/1000 -> 6e-09 | P22: =4*POWER(10,-15) -> 4e-15 | T22: =7*POWER(10,-15) -> 7e-15 | U22: Fagerbakke, Heldal and Norland 1996 | W22: 0026 to 15.8 microm3, 4 fg to 1.9 pg.
C23: 4 | D23: Bacteria | E23: Bacteria - heterotroph | F23: marine, brakish and freshwater bacteria | H23: 15.8 | I23: =H23/1000000 -> 1.58e-05 | N23: =I23/1000 -> 1.58e-08 | P23: =1.9*POWER(10,-12) -> 1.9e-12 | T23: =530*POWER(10,-15) -> 5.3e-13 | U23: Fagerbakke, Heldal and Norland 1996 | W23: 0026 to 15.8 microm3, 4 fg to 1.9 pg.
C24: 4 | D24: Bacteria | E24: Bacteria - heterotroph | F24: E. coli | J24: =Q24*1000000 -> 6.65e-09 | Q24: 6.65e-15 | U24: Ilic et al. 2001
C25: 4 | D25: Bacteria | E25: Bacteria - heterotroph | F25: E.coli from 2 lakes - small | K25: =V25/POWER(10,9) -> 3e-09 | L25: =K25/2 -> 1.5e-09 | R25: =K25/POWER(10,6) -> 3e-15 | T25: =R25/2 -> 1.5e-15 | U25: Loferer-Krossbacher et al. 1998 | V25: 3 | W25: DW of E. coli cells ranged from 3 to 1,172 fg; carbon is 50% of DW
C26: 4 | D26: Bacteria | E26: Bacteria - heterotroph | F26: E.coli from 2 lakes - large | K26: =V26/POWER(10,9) -> 1.777e-06 | L26: =K26/2 -> 8.885e-07 | R26: =K26/POWER(10,6) -> 1.777e-12 | T26: =R26/2 -> 8.885e-13 | U26: Loferer-Krossbacher et al. 1998 | V26: 1777 | W26: DW of E. coli cells ranged from 83 to 1,172 fg
C27: 4 | D27: Bacteria | E27: Bacteria - heterotroph | F27: Groundwater bacteria large | H27: 0.09 | I27: =H27/1000000 -> 9e-08 | U27: Marxen 1988
C28: 4 | D28: Bacteria | E28: Bacteria - general | F28: Average benthic, marine prokaryote | L28: =T28*1000000 -> 1.1e-08 | T28: =11*POWER(10,-15) -> 1.1e-14 | U28: Bar-On et al. 2018 | W28: 11 fgC/cell
D29: Bacteria | E29: Bacteria - general | H29: 0.026 | K29: =19.7/POWER(10,9) -> 1.97e-08 | L29: =10.4/POWER(10,9) -> 1.04e-08 | R29: =K29/POWER(10,6) -> 1.97e-14 | T29: =L29/POWER(10,6) -> 1.04e-14 | U29: Simon and Azam 1989 | V29: 9.9 | W29: fg protein
D30: Bacteria | E30: Bacteria - general | H30: 0.4 | K30: =95.8/POWER(10,9) -> 9.58e-08 | L30: =53.3/POWER(10,9) -> 5.33e-08 | R30: =K30/POWER(10,6) -> 9.58e-14 | T30: =L30/POWER(10,6) -> 5.33e-14 | U30: Simon and Azam 1989
C31: 4 | D31: Bacteria | E31: Bacteria - general | F31: Constant biomass model for bacteria | L31: =T31*1000000 -> 2e-08 | T31: =20*0.000000000000001 -> 2e-14 | U31: Lee and Fuhrman 1987
C32: 4 | D32: Bacteria | E32: Bacteria - general | F32: Groundwater bacteria small | H32: 0.072 | I32: =H32/1000000 -> 7.2e-08 | N32: =I32/1000 -> 7.2e-11 | U32: Marxen 1988 | W32: V in microm3
C33: 4 | D33: Bacteria | E33: Bacteria - general | F33: Aquatic prokaryote small | L33: =T33*1000000 -> 5e-09 | T33: =5*0.000000000000001 -> 5e-15 | U33: Whitman et al. 1998
C34: 4 | D34: Bacteria | E34: Bacteria - general | F34: Aquatic prokaryotes large | L34: =T34*1000000 -> 2e-08 | T34: =20*0.000000000000001 -> 2e-14 | U34: Whitman et al. 1998
C35: 4 | D35: Bacteria | E35: Bacteria - general | F35: Average benthic prokaryotes | L35: =T35*1000000 -> 1e-08 | T35: =10*0.000000000000001 -> 1e-14 | U35: Whitman et al. 1998
C36: 4 | D36: Bacteria | E36: Bacteria - general | F36: Average planktonic prokayote | L36: =T36*1000000 -> 2e-08 | T36: =20*0.000000000000001 -> 2e-14 | U36: Whitman et al. 1998
C37: 4 | D37: Bacteria | E37: Bacteria | F37: small | Q37: 1e-15 | U37: Andersen et al. 2015 2015
C38: 4 | D38: Bacteria | E38: Bacteria | F38: small | O38: 1e-14 | U38: Hatton et al. 2021 | V38: smallest cell | W38: bacteria body mass range 10-14 10-11
C39: 4 | D39: Bacteria | E39: Bacteria | F39: large | O39: 1e-11 | U39: Hatton et al. 2021 | W39: bacteria body mass range 10-14 10-12
C40: 4 | D40: Bacteria | E40: Bacteria | H40: 0.072 | U40: Marxen 1988
...

Sheet 1b
A3: Row Labels | B3: Min of gC/ind. | C3: Max of gC/ind.2
A4: 1 | B4: 1.5e-07 | C4: 0.0001
A5: Macrofauna | B5: 1.5e-07 | C5: 0.0001 | E5: Macrofauna | F5: 1.5e-07 | G5: 0.0001
A6: 2 | B6: 3.9543161e-09 | C6: 0.0001 | E6: 2 | F6: 3.9543161e-09 | G6: 0.0001
A7: Micro-metazoan | B7: 3.9543161e-09 | C7: 0.0001 | E7: Micro-metazoan | F7: 3.9543161e-09 | G7: 0.0001
A8: 3 | B8: 8e-13 | C8: 1.8801287e-06 | E8: 3 | F8: 8e-13 | G8: 1.8801287e-06
A9: Protists | B9: 8e-13 | C9: 1.8801287e-06 | E9: Protists | F9: 8e-13 | G9: 1.8801287e-06
A10: 4 | B10: 5e-15 | C10: 5.86e-13 | E10: 4 | F10: 5e-15 | G10: 5.86e-13
A11: Bacteria | B11: 5e-15 | C11: 5.86e-13 | E11: Bacteria | F11: 5e-15 | G11: 5.86e-13
A12: 5 | B12: 2e-17 | C12: 1e-15 | E12: 5 | F12: 2e-17 | G12: 1e-15
A13: Viruses | B13: 2e-17 | C13: 1e-15 | E13: Viruses | F13: 2e-17 | G13: 1e-15
A14: (blank)
A15: (blank)
A16: Grand Total | B16: 2e-17 | C16: 0.0001
U48: Katrin Layer data unpubl.

Sheet 2
A1: Background
A2: Conversions length and weight
A3: The below tables were used to establish body size realms and orders of magnitude difference.
B5: Units in writing | G5: Units decimals | L5: Units scientific | Q5: Realm | X5: Units to demonstrate order of magnitude | Z5: Number | AA5: log10
Z6: 0.02 | AA6: =LOG(Z6) -> -1.69897
B7: milligram | C7: = | D7: 10−3 | E7: g | G7: milligram | H7: = | I7: =POWER(10,-3) -> 0.001 | J7: g | L7: milligram | M7: = | N7: =POWER(10,-3) -> 0.001 | O7: g | Q7: milligram | R7: from | S7: 10−3 | T7: to | U7: 1 | V7: g | X7: =LOG(I7) -> -3 | Z7: 0.2 | AA7: =LOG(Z7) -> -0.69897
B8: microgram | C8: = | D8: 10−6 | E8: g | G8: microgram | H8: = | I8: =I7/1000 -> 1e-06 | J8: g | L8: microgram | M8: = | N8: =N7/1000 -> 1e-06 | O8: g | Q8: microgram | R8: from | S8: 10−6 | T8: to | U8: 10−3 | V8: g | X8: =LOG(I8) -> -6 | Z8: 2 | AA8: =LOG(Z8) -> 0.30103
B9: nanogram | C9: = | D9: 10−9 | E9: g | G9: nanogram | H9: = | I9: =I8/1000 -> 1e-09 | J9: g | L9: nanogram | M9: = | N9: =N8/1000 -> 1e-09 | O9: g | Q9: nanogram | R9: from | S9: 10−9 | T9: to | U9: 10−6 | V9: g | X9: =LOG(I9) -> -9 | Z9: 20 | AA9: =LOG(Z9) -> 1.30103
B10: picogram | C10: = | D10: 10−12 | E10: g | G10: picogram | H10: = | I10: =I9/1000 -> 1e-12 | J10: g | L10: picogram | M10: = | N10: =N9/1000 -> 1e-12 | O10: g | Q10: picogram | R10: from | S10: 10−12 | T10: to | U10: 10−9 | V10: g | X10: =LOG(I10) -> -12 | Z10: 200 | AA10: =LOG(Z10) -> 2.30103
B11: femtogram | C11: = | D11: 10−15 | E11: g | G11: femtogram | H11: = | I11: =I10/1000 -> 1e-15 | J11: g | L11: femtogram | M11: = | N11: =N10/1000 -> 1e-15 | O11: g | Q11: femtogram | R11: from | S11: 10−15 | T11: to | U11: 10−12 | V11: g | X11: =LOG(I11) -> -15 | Z11: 2000 | AA11: =LOG(Z11) -> 3.30103
B12: attogram | C12: = | D12: 10−18 | E12: g | G12: attogram | H12: = | I12: =I11/1000 -> 1e-18 | J12: g | L12: attogram | M12: = | N12: =N11/1000 -> 1e-18 | O12: g | Q12: attogram | R12: from | S12: 10−18 | T12: to | U12: 10−15 | V12: g | X12: =LOG(I12) -> -18 | Z12: 1 | AA12: =LOG(Z12) -> 0
B13: zeptogram | C13: = | D13: 10−21 | E13: g | G13: zeptogram | H13: = | I13: =I12/1000 -> 1e-21 | J13: g | L13: zeptogram | M13: = | N13: =N12/1000 -> 1e-21 | O13: g | Q13: zeptogram | R13: from | S13: 10−21 | T13: to | U13: 10−18 | V13: g | X13: =LOG(I13) -> -21 | Z13: 2 | AA13: =LOG(Z13) -> 0.30103
B14: yoctogram | C14: = | D14: 10−24 | E14: g | G14: yoctogram | H14: = | I14: =I13/1000 -> 1e-24 | J14: g | L14: yoctogram | M14: = | N14: =N13/1000 -> 1e-24 | O14: g | Q14: yoctogram | R14: from | S14: 10−24 | T14: to | U14: 10−21 | V14: g | X14: -24 | Z14: 3 | AA14: =LOG(Z14) -> 0.47712125
Z15: 10 | AA15: =LOG(Z15) -> 1
B16: centimetre | C16: = | D16: 10−2 | E16: m | G16: centimetre | H16: = | I16: 0.01 | J16: m | L16: centimetre | M16: = | N16: 0.01 | O16: m | Q16: centimetre | R16: from | S16: 0.01 | T16: to | U16: 1 | V16: m | X16: =LOG(I16) -> -2 | Z16: 100 | AA16: =LOG(Z16) -> 2
B17: millimetre | C17: = | D17: 10−3 | E17: m | G17: millimetre | H17: = | I17: =POWER(10,-3) -> 0.001 | J17: m | L17: millimetre | M17: = | N17: =POWER(10,-3) -> 0.001 | O17: m | Q17: millimetre | R17: from | S17: 10−3 | T17: to | U17: 0.01 | V17: m | X17: =LOG(I17) -> -3 | Z17: 1000 | AA17: =LOG(Z17) -> 3
B18: micrometre | C18: = | D18: 10−6 | E18: m | G18: micrometre | H18: = | I18: =I17/1000 -> 1e-06 | J18: m | L18: micrometre | M18: = | N18: =N17/1000 -> 1e-06 | O18: m | Q18: micrometre | R18: from | S18: 10−6 | T18: to | U18: 10−3 | V18: m | X18: =LOG(I18) -> -6 | Z18: 10000 | AA18: =LOG(Z18) -> 4
B19: nanometre | C19: = | D19: 10−9 | E19: m | G19: nanometre | H19: = | I19: =I18/1000 -> 1e-09 | J19: m | L19: nanometre | M19: = | N19: =N18/1000 -> 1e-09 | O19: m | Q19: nanometre | R19: from | S19: 10−9 | T19: to | U19: 10−6 | V19: m | X19: =LOG(I19) -> -9 | Z19: 100000 | AA19: =LOG(Z19) -> 5
Q21: =0.02/1000/1000/1000/1000/1000 -> 2e-17
AA48: Katrin Layer data unpubl.

Sheet 3
A1: Background
A2: Conversions for body volume
B3: a) Length to volume | P3: b) Volume to weight | AD3: Dalton to weight, particle number to weight | AF3: Conversions of volumes
B4: 1 | C4: cm3 | D4: centimetre cubed | E4: = | F4: 1 | G4: ml | H4: millilitre | I4: = | J4: 1 | K4: ml | L4: = | M4: =POWER(10,-3) -> 0.001 | N4: L | P4: 1 | Q4: mL | R4: millilitre | S4: = | T4: 1 | U4: g | V4: gram | W4: = | X4: 1 | Y4: g | Z4: = | AA4: 10−3 | AB4: kg | AD4: 1 Dalton = 1.66054e-24g
B5: 1 | C5: mm3 | D5: millimetre cubed | E5: = | F5: 1 | G5: µL | H5: microlitre | I5: = | J5: =M5*1000 -> 0.001 | K5: ml | L5: = | M5: =POWER(10,-6) -> 1e-06 | N5: L | P5: 1 | Q5: µL | R5: microlitre | S5: = | T5: 1 | U5: mg | V5: milligram | W5: = | X5: 10−3 | Y5: g | Z5: = | AA5: 10−6 | AB5: kg | AD5: 1 Dalton = 1.66054 yoctogram | AF5: 1 cubic nanometre = 10-18 cubic mm
P6: 1 | Q6: nL | R6: nanolitre | S6: = | T6: 1 | U6: µg | V6: microgram | W6: = | X6: 10−6 | Y6: g | Z6: = | AA6: 10−9 | AB6: kg | AD6: Virus 10E3 Megadalton (MD) ≈ 1 fg (Bar-On et al. 2022) | AF6: 1 cubic micrometre = 10-9 cubic mm
P7: 1 | Q7: pL | R7: picolitre | S7: = | T7: 1 | U7: ng | V7: nanogram | W7: = | X7: 10−9 | Y7: g | Z7: = | AA7: 10−12 | AB7: kg | AD7: Virus 10E3 Dalton ≈ 1 zg (Bar-On et al. 2022) | AF7: 1 cubic mm = 10-9 cubic m
B8: 1 | C8: µm3 | D8: micrometre cubed | E8: = | F8: 1 | G8: fL | H8: femtolitre | I8: = | J8: =POWER(10,-12) -> 1e-12 | K8: ml | L8: = | M8: =POWER(10,-15) -> 1e-15 | N8: L | P8: 1 | Q8: fL | R8: femtolitre | S8: = | T8: 1 | U8: pg | V8: picogram | W8: = | X8: 10−12 | Y8: g | Z8: = | AA8: 10−15 | AB8: kg | AD8: Virus Dalton ≈ 1 yg (Bar-On et al. 2022)
P9: 1 | Q9: aL | R9: attolitre | S9: = | T9: 1 | U9: fg | V9: femtogram | W9: = | X9: 10−15 | Y9: g | Z9: = | AA9: 10−18 | AB9: kg
P10: 1 | Q10: zL | R10: zeptolitre | S10: = | T10: 1 | U10: ag | V10: attogram | W10: = | X10: 10−18 | Y10: g | Z10: = | AA10: 10−21 | AB10: kg | AD10: Avogadro's number* 6.022 × 10²³
B11: 1 | C11: nm3 | D11: nanometre cubed | E11: = | F11: 1 | G11: yL | H11: yoctolitre | I11: = | J11: =M11*1000 -> 1e-21 | K11: ml | L11: = | M11: =POWER(10,-24) -> 1e-24 | N11: L | P11: 1 | Q11: yL | R11: yoctolitre | S11: = | T11: 1 | U11: zg | V11: zeptogram | W11: = | X11: 10−21 | Y11: g | Z11: = | AA11: 10−24 | AB11: kg
AD12: *number of units in one mole of any substance (defined as its molecular weight in grams)
AA48: Katrin Layer data unpubl.

Sheet 4
A1: Methods body mass | B1: table: simple approaches to calcualte weight from body dimensions, that assume, simple geometric shapes and fixed ratios
A2: Worked examples
D4: L (m) | E4: L (µm) | F4: W (µm) | G4: d (µm) | H4: Shape | I4: Volume fL (µm3) | J4: Volume nL and water weight in µg | K4: µg FW of organisms applying conversion factor a) | L4: µg DW of organism if DW is x% of FW; applying conversion factor b) | M4: µg CW of organism if CW is x% of DW; applying conversion factor c) | N4: From V in fL to µg C using one 'combined' factor; applying conversion factor d) | O4: g CW of orgabism | P4: a) density (conversion factor) to estimate wetweight from volume | Q4: b) conversion factor to estimate dry weight from fresh weight | R4: c) conversion factor to estiamte carbon content from dry weight | S4: d) one-pass factor from volume in fL to microg C | T4: Volume (V) equation | U4: Volume equation solved for L, W and d
D5: =E5/POWER(10,6) -> 1e-07 | E5: 0.1 | F5: na | G5: na | H5: sphere | I5: =(4/3)*PI()*POWER((E5/2),3) -> 0.00052359878 | J5: =I5/POWER(10,6) -> 5.2359878e-10 | K5: =J5*P$5 -> 5.7595865e-10 | L5: =K5*Q$5 -> 1.4398966e-10 | M5: =L5*R$5 -> 5.7595865e-11 | N5: =J5*S$5 -> 5.7595865e-11 | O5: =M5/POWER(10,6) -> 5.7595865e-17 | P5: 1.1 | Q5: 0.25 | R5: 0.4 | S5: =P5*Q5*R5 -> 0.11 | T5: V=4/3πr3 | U5: V=4/3π(L/2)3
D6: =E6/POWER(10,6) -> 1e-06 | E6: 1 | F6: na | G6: na | H6: sphere | I6: =(4/3)*PI()*POWER((E6/2),3) -> 0.52359878 | J6: =I6/POWER(10,6) -> 5.2359878e-07 | K6: =J6*P$5 -> 5.7595865e-07 | L6: =K6*Q$5 -> 1.4398966e-07 | M6: =L6*R$5 -> 5.7595865e-08 | N6: =J6*S$5 -> 5.7595865e-08 | O6: =M6/POWER(10,6) -> 5.7595865e-14 | P6: " | Q6: " | R6: " | S6: " | T6: V=4/3πr3 | U6: V=4/3π(L/2)3
D7: =E7/POWER(10,6) -> 1e-05 | E7: 10 | F7: na | G7: na | H7: sphere | I7: =(4/3)*PI()*POWER((E7/2),3) -> 523.59878 | J7: =I7/POWER(10,6) -> 0.00052359878 | K7: =J7*P$5 -> 0.00057595865 | L7: =K7*Q$5 -> 0.00014398966 | M7: =L7*R$5 -> 5.7595865e-05 | N7: =J7*S$5 -> 5.7595865e-05 | O7: =M7/POWER(10,6) -> 5.7595865e-11 | P7: " | Q7: " | R7: " | S7: " | T7: V=4/3πr3 | U7: V=4/3π(L/2)3
D8: =E8/POWER(10,6) -> 0.0001 | E8: 100 | F8: na | G8: na | H8: sphere | I8: =(4/3)*PI()*POWER((E8/2),3) -> 523598.78 | J8: =I8/POWER(10,6) -> 0.52359878 | K8: =J8*P$5 -> 0.57595865 | L8: =K8*Q$5 -> 0.14398966 | M8: =L8*R$5 -> 0.057595865 | N8: =J8*S$5 -> 0.057595865 | O8: =M8/POWER(10,6) -> 5.7595865e-08 | P8: " | Q8: " | R8: " | S8: " | T8: V=4/3πr3 | U8: V=4/3π(L/2)3
D9: =E9/POWER(10,6) -> 0.001 | E9: 1000 | F9: na | G9: na | H9: sphere | I9: =(4/3)*PI()*POWER((E9/2),3) -> 5.2359878e+08 | J9: =I9/POWER(10,6) -> 523.59878 | K9: =J9*P$5 -> 575.95865 | L9: =K9*Q$5 -> 143.98966 | M9: =L9*R$5 -> 57.595865 | N9: =J9*S$5 -> 57.595865 | O9: =M9/POWER(10,6) -> 5.7595865e-05 | P9: " | Q9: " | R9: " | S9: " | T9: V=4/3πr3 | U9: V=4/3π(L/2)3
D10: =E10/POWER(10,6) -> 0.0001 | E10: 100 | F10: 30 | G10: 20 | H10: 1/2 cone | I10: =(1/3)*E10*PI()*(POWER((F10/2),2)) -> 23561.945 | J10: =I10/POWER(10,6) -> 0.023561945 | K10: =J10*P$5 -> 0.025918139 | L10: =K10*Q$5 -> 0.0064795348 | M10: =L10*R$5 -> 0.0025918139 | N10: =J10*S$5 -> 0.0025918139 | O10: =M10/POWER(10,6) -> 2.5918139e-09 | P10: " | Q10: " | R10: " | S10: " | T10: V=1/3hπr²
D11: =E11/POWER(10,6) -> 0.0001 | E11: 100 | F11: 30 | G11: na | H11: cylinder | I11: =PI()*(POWER((F11/2),2))*E11 -> 70685.835 | J11: =I11/POWER(10,6) -> 0.070685835 | K11: =J11*P$5 -> 0.077754418 | L11: =K11*Q$5 -> 0.019438605 | M11: =L11*R$5 -> 0.0077754418 | N11: =J11*S$5 -> 0.0077754418 | O11: =M11/POWER(10,6) -> 7.7754418e-09 | P11: " | Q11: " | R11: " | S11: " | T11: V=πr²h | U11: V=π*(W/2)2*L
D12: =E12/POWER(10,6) -> 0.0001 | E12: 100 | F12: 30 | G12: na | H12: prolate spheroid | I12: =(4/3)*PI()*(E12/2)*POWER((F12/2),2) -> 47123.89 | J12: =I12/POWER(10,6) -> 0.04712389 | K12: =J12*P$5 -> 0.051836279 | L12: =K12*Q$5 -> 0.01295907 | M12: =L12*R$5 -> 0.0051836279 | N12: =J12*S$5 -> 0.0051836279 | O12: =M12/POWER(10,6) -> 5.1836279e-09 | P12: " | Q12: " | R12: " | S12: " | T12: V=4/3πab2 | U12: V=L*W2*(π/6)
D13: =E13/POWER(10,6) -> 0.0001 | E13: 100 | F13: 3 | G13: 20 | H13: ellipsoid | I13: =(4/3)*PI()*(E13/2*F13/2*G13/2) -> 3141.5927 | J13: =I13/POWER(10,6) -> 0.0031415927 | K13: =J13*P$5 -> 0.0034557519 | L13: =K13*Q$5 -> 0.00086393798 | M13: =L13*R$5 -> 0.00034557519 | N13: =J13*S$5 -> 0.00034557519 | O13: =M13/POWER(10,6) -> 3.4557519e-10 | P13: " | Q13: " | R13: " | S13: " | T13: V=4/3πabc
C16: Shape and volume | E16: Hillebrand et al. 1999, Marine and freshwater microalgal genera; species specific, 21 possible geometric shapes from multiple dimensions
E17: Sacca 2016, plankton, 2 dimensional shapes
E18: Feller & Warwick 1988 V (nl) = a*b²*factor depending on form and taxon, see tap 2
E19: Ruttner-Kolisko 1977; rotifers, sphere, half cone, cylinder, ellipsoid
E20: Reiss and Schmid-Araya 2010, ciliates and meiofauna, sphere, half cone, cylinder, ellipsoid
E21: Pernice et al. 2015, heterotrophic pelagic marine protists prolate spheroid shapes
C23: fresh weight (FW) of organisms in µg if density is x | E23: Feller & Warwick 1988 assume density to be 1.13
E24: Reiss and Schmid-Araya 2010 assume density of 1.1
C26: Drweight content | E26: Reiss and Schmid-Araya 2010 assume 25% of DW
C28: Carbon content | E28: Reiss and Schmid-Araya 2010 assume 40% of DW
E29: Gaedke 1992 assume 50% of DW for rotifers
C31: From V to C using 'simple' conversion factors | E31: Gaedke 1992 conversion factor C µg= x * (cell vol., µm3): APP 0.19 ; Heterotrophic flagellates 0.22; Phytoplankton 0.11; Ciliates 0.11
E32: Fry 1990 conversion factor C fg = 319 * (cell vol., µm3): prokaryotes
Z41: Katrin Layer data unpubl.

Sheet 5
A1: Methods mody mass | K1: As given by authors | Q1: Worked example | Z1: Units as used by the authors
A2: literature overview of how to estimate body mass for specific taxa | C2: Group | D2: Reference | E2: Methods-general | F2: Methods - organism shape assumed | G2: Example for individual (or object) length in µm | H2: gC per example individual | I2: pgC/µm3 | J2: Volume estimated as | K2: L | L2: W | M2: V | N2: d | O2: Single pass factor | Q2: Example L in µm | R2: Example W in µm | S2: Volume in µm3, i.e. fL | T2: Volume in nl | U2: Fresh weight in µg | V2: Dry weight in µg | W2: Carbon µg/ind. | X2: Carbon g/ind. | Z2: Original Measurements | AA2: Dry weight in fg | AB2: Carbon fg/ind. | AC2: Protein weight fg | AD2: Volume in cm3 | AE2: formula used by authors | AF2: Dry weight in pg, i.e. fL | AG2: Carbon pg/ind. | AH2: Carbon fg/ind. | AI2: a | AJ2: b | AK2: dry weight in mg
A3: L=length, W=width, V=Volume, d=Density, DW=Dryweight, FW=fresh weight, CW=carbon weight, gC=gram carbon. 1fL=1µm3. | C3: Viruses
C4: enveloped viruses | D4: this publication | E4: Assuming that viruses weigh 106 daltons and hence all have a weight of just over 1.6*10-17 gC; daltons give the weight in yoctograms | F4: no shape specified | G4: na | H4: =X4 -> 1.66054e-17 | I4: na | J4: na | K4: na | L4: na | M4: na | N4: na | Q4: 0.1 | R4: 0.1 | S4: na | T4: na | U4: na | V4: na | W4: na | X4: =POWER(10,7)*1.66054*POWER(10,-24) -> 1.66054e-17 | Z4: dalton for weight in yoctogram | AA4: na | AB4: na
C5: bacteriophage | D5: Bar-on 2020 | E5: Jover et al. 2014 equations; R-code available | F5: head as a spherical shell | G5: 0.05 | H5: 2e-17 | Q5: 0.05
C6: enveloped virus SARS-Cov | D6: Bar-on et al. 2018 | E6: Multiply the total number of atoms by the molecular weight of carbon and divide by Avogadro's number | F6: no shape specified | G6: na | H6: 1e-17 | I6: a | J6: nm3 | K6: na | L6: na | M6: na | N6: na | Q6: 0.1 | R6: 0.1 | S6: na | T6: na | U6: na | V6: na | W6: na | X6: na | Z6: length and width in nm | AA6: na | AB6: na
C7: Overestimation with exaggerated shape made out of carbon | F7: sphere | G7: 0.05 | H7: =X7 -> 1.4398966e-16 | I7: =X7/S7*POWER(10,15) -> 550 | N7: 2.2 | Q7: 0.05 | R7: 0.05 | S7: =4/3*PI()*(Q7/2)*POWER(R7,2) -> 0.00026179939 | T7: =((Q7*(POWER(R7,2))*PI())/6)/1000000 -> 6.5449847e-11 | U7: =T7*N7 -> 1.4398966e-10 | X7: =U7/POWER(10,6) -> 1.4398966e-16
C8: Prokaryotes
C9: Bacterium with prolate spheroid shape | D9: this publication | E9: L in µm; W in µm, V in µm3; ρ =1.1; FW = V*d, DW is 25% of FW, CW is 50% of DW. | F9: prolate spheroid | G9: 1 | H9: =X9 -> 7.1994832e-14 | I9: =X9/S9*POWER(10,15) -> 34.375 | J9: in µm3 (=fL) | K9: µm | L9: µm | N9: 1.1 | Q9: 1 | R9: 1 | S9: =4/3*PI()*(Q9/2)*POWER(R9,2) -> 2.0943951 | T9: =((Q9*(POWER(R9,2))*PI())/6)/1000000 -> 5.2359878e-07 | U9: =T9*1.1 -> 5.7595865e-07 | V9: =U9*0.25 -> 1.4398966e-07 | W9: =V9*0.5 -> 7.1994832e-08 | X9: =W9/1000000 -> 7.1994832e-14 | Z9: length, width in µm | AA9: na | AB9: na
C10: Bacteria | D10: Lee and Fuhrman 1987 | E10: Constant biomass model, all bacteria weigh the same; (they also report C= 0.38 g of C cm-3) | F10: na | G10: ' | H10: =X10 -> 2e-14 | I10: na | J10: na | K10: µm | L10: µm | M10: na | N10: na | Q10: 1 | R10: 1 | S10: 0.036 - 0.073 | T10: na | U10: na | V10: na | W10: na | X10: =20*POWER(10,-15) -> 2e-14 | Z10: na | AA10: na | AB10: na
C11: Bacteria | D11: Watson et al. 1977 | E11: L in µm; W in µm, V in µm3; CW (fg) = 6.35*V(µm3). | F11: different shapes | G11: ' | H11: =X11 -> 1.3299409e-14 | I11: =X11/S11*POWER(10,15) -> 6.35 | J11: Volume = 1/4(Trd2h). bVolume = '/6(7Td3). | K11: µm | L11: µm | M11: µm3 | N11: na | O11: 6.35 | Q11: 1 | R11: 1 | S11: =4/3*PI()*(Q11/2)*POWER(R11,2) -> 2.0943951 | W11: =AB11*POWER(10,-9) -> 1.3299409e-08 | X11: =W11/1000000 -> 1.3299409e-14 | Z11: μm | AA11: na | AB11: =S11*O11 -> 13.299409
C12: Bacteria, size classes of 0.4, 0.6 and 0.8 µm spheres | D12: Fuhrman and Azam 1980 | E12: L in µm; W in µm, V in µm3; CW (g) = 1.21*10-13*V(µm3). | F12: sphere | G12: ' | H12: =X12 -> 2.5342181e-13 | I12: =X12/S12*POWER(10,15) -> 121 | J12: in µm3 (=fL) | K12: µm | L12: µm | M12: µm3 | N12: na | O12: =1.21*POWER(10,-13) -> 1.21e-13 | Q12: 1 | R12: 1 | S12: =4/3*PI()*(Q12/2)*POWER(R12,2) -> 2.0943951 | T12: =((Q12*(POWER(R12,2))*PI())/6)/1000000 -> 5.2359878e-07 | U12: na | V12: na | W12: na | X12: =O12*S12 -> 2.5342181e-13 | Z12: length in µm | AA12: na | AB12: na
C13: Bacteria | D13: Findlay et al. 2002 | E13: bacteria weigh 2*10-14 gC / cell | F13: na | G13: na | H13: =2*POWER(10,-14) -> 2e-14 | I13: =AA13 -> 0.1 | S13: 0.2 | AA13: =100/1000 -> 0.1
C14: Bacteria | D14: Marxen 2006 | E14: L in µm; W in µm, V in µm3; CW (fg) = 100*V(µm3). Citing Findlay et al. (2002). | F14: no shape specified | G14: ' | H14: =X14 -> 2.0943951e-13 | I14: =X14/S14*POWER(10,15) -> 100 | J14: in µm3 (=fL) | K14: µm | L14: µm | M14: na | N14: na | O14: 100 | Q14: 1 | R14: 1 | S14: =4/3*PI()*(Q14/2)*POWER(R14,2) -> 2.0943951 | T14: na | U14: na | V14: na | W14: =AB14*POWER(10,-9) -> 2.0943951e-07 | X14: =W14/1000000 -> 2.0943951e-13 | Z14: μm | AA14: na | AB14: =S14*O14 -> 209.43951
C15: Bacteria | D15: Fry 1990 | E15: L in µm; W in µm, V in µm3; CW (fg) = 310*V(µm3). | F15: no shape specified | G15: ' | H15: =X15 -> 6.4926248e-13 | I15: =X15/S15*POWER(10,15) -> 310 | J15: in µm3 (=fL) | K15: µm | L15: µm | M15: na | N15: na | O15: 310 | Q15: 1 | R15: 1 | S15: =4/3*PI()*(Q15/2)*POWER(R15,2) -> 2.0943951 | T15: na | U15: na | V15: na | W15: =AB15*POWER(10,-9) -> 6.4926248e-07 | X15: =W15/1000000 -> 6.4926248e-13 | Z15: μm | AA15: na | AB15: =S15*O15 -> 649.26248 | AH15: =310*S15 -> 649.26248
C16: Bacteria | D16: Simon & Azam 1989 | E16: L in µm; W in µm, V in µm3; protein content (fg) =88.6*V(µm3)0.59. CW is 54% of protein content. | F16: rod shaped cells are cylinders with a hemispherical cap, and cocci are spheres | G16: ' | H16: =X16 -> 7.4003467e-14 | I16: =X16/S16*POWER(10,15) -> 35.334053 | J16: in µm3 (=fL) | K16: µm | L16: µm | M16: na | N16: na | Q16: 1 | R16: 1 | S16: =4/3*PI()*(Q16/2)*POWER(R16,2) -> 2.0943951 | W16: =AB16*POWER(10,-9) -> 7.4003467e-08 | X16: =W16/1000000 -> 7.4003467e-14 | Z16: μm | AA16: na | AB16: =AC16*54/100 -> 74.003467 | AC16: =88.6*POWER(S16,0.59) -> 137.04346
C17: Bacteria, cocci and rods | D17: Loferer-Krossbacher et al. 1998 | E17: L in µm; W in µm, V in µm3; DW (fg) =435*V(µm3)0.86. CW is 50% of DW. | F17: cylinders with hemispherical ends at each side | G17: ' | H17: =X17 -> 1.2468037e-13 | I17: =X17/S17*POWER(10,15) -> 238.12196 | J17: in µm3 (=fL) | K17: µm | L17: µm | M17: na | N17: na | Q17: 1 | R17: 1 | S17: =((POWER(R17,2)*PI()/4)*(Q17-R17)+PI()*POWER(R17,3)/6) -> 0.52359878 | T17: na | U17: na | V17: =AA17*POWER(10,-9) -> 2.4936074e-07 | W17: =V17*0.5 -> 1.2468037e-07 | X17: =W17/1000000 -> 1.2468037e-13 | Z17: μm | AA17: =435*POWER(S17,0.86) -> 249.36074 | AB17: na
C18: Bacteria | D18: Bratbak 1985 | E18: L in µm; W in µm, V in µm3; CW (g) = 5.6*10-13*V(µm3). | F18: cocci and rods | G18: ' | H18: =X18 -> 1.1728613e-12 | I18: =X18/S18*POWER(10,15) -> 560 | J18: (7r/4)W2(L- W/3) | K18: µm | L18: µm | M18: na | N18: na | O18: =5.6*POWER(10,-13) -> 5.6e-13 | Q18: 1 | R18: 1 | S18: =4/3*PI()*(Q18/2)*POWER(R18,2) -> 2.0943951 | T18: =((Q18*(POWER(R18,2))*PI())/6)/1000000 -> 5.2359878e-07 | U18: na | V18: na | W18: na | X18: =O18*S18 -> 1.1728613e-12 | AA18: na | AB18: na
C19: Bacteria | D19: Bratbak & Dundas 1984 | E19: L in µm; W in µm, V in cm3; CW (g) = 0.22*V(cm3). | F19: no shape specified | G19: ' | H19: =X19 -> 4.6076692e-13 | I19: =X19/S19*POWER(10,15) -> 220 | J19: in µm3 (=fL) | K19: µm | L19: µm | M19: na | N19: 1.1 | Q19: 1 | R19: 1 | S19: =4/3*PI()*(Q19/2)*POWER(R19,2) -> 2.0943951 | T19: =((Q19*(POWER(R19,2))*PI())/6)/1000000 -> 5.2359878e-07 | U19: =T19*1.1 -> 5.7595865e-07 | V19: =U19*0.4 -> 2.3038346e-07 | W19: na | X19: =0.22*AD19 -> 4.6076692e-13 | Z19: μm | AB19: na | AD19: =S19*POWER(10,-12) -> 2.0943951e-12
C20: Overestimation with exaggerated shape made out of carbon | F20: perfect sphere | G20: sphere 1µm long | H20: =X20 -> 1.1519173e-12 | I20: =X20/S20*POWER(10,15) -> 550 | N20: 2.2 | Q20: 1 | R20: 1 | S20: =4/3*PI()*(Q20/2)*POWER(R20,2) -> 2.0943951 | T20: =((Q20*(POWER(R20,2))*PI())/6)/1000000 -> 5.2359878e-07 | U20: =T20*N20 -> 1.1519173e-06 | X20: =U20/POWER(10,6) -> 1.1519173e-12
C21: Protists
C22: Protist with prolate spheroid shape | D22: Reiss and Schmid-Araya 2010 | E22: L in µm; W in µm, V in µm3; ρ =1.1; FW = V*d, DW is 25% of FW, CW is 40% of DW. | F22: prolate spheroid | G22: 50 | H22: =X22 -> 7.9994257e-10 | I22: =X22/S22*POWER(10,15) -> 27.5 | J22: prolate spheroid | K22: µm | L22: µm | M22: na | N22: na | Q22: 50 | R22: =Q22/3 -> 16.666667 | S22: =4/3*PI()*(Q22/2)*POWER(R22,2) -> 29088.821 | T22: =((Q22*(POWER(R22,2))*PI())/6)/1000000 -> 0.0072722052 | U22: =T22*1.1 -> 0.0079994257 | V22: =U22*0.25 -> 0.0019998564 | W22: =V22*0.4 -> 0.00079994257 | X22: =W22/1000000 -> 7.9994257e-10 | Z22: length, width in µm | AB22: na
C23: Average protist' | D23: Bar-On 2020 | E23: V in µm3 | S23: 4 | X23: =0.8*POWER(10,-12) -> 8e-13
C24: Dinoflagellates, marine | D24: Menden-Deuer & Lessard 2000 | E24: L in µm; W in µm, V in µm3; CW (pg) = 0.76*V(µm3)0.82 | F24: no shape specified | G24: ' | H24: =X24 -> 3.4759139e-09 | I24: =X24/S24*POWER(10,15) -> 119.49312 | K24: µm | L24: µm | M24: na | N24: na | Q24: 50 | R24: =Q24/3 -> 16.666667 | S24: =4/3*PI()*(Q24/2)*POWER(R24,2) -> 29088.821 | T24: =((Q24*(POWER(R24,2))*PI())/6)/1000000 -> 0.0072722052 | U24: na | V24: a | W24: =AG24*POWER(10,-6) -> 0.0034759139 | X24: =W24/1000000 -> 3.4759139e-09 | AB24: na | AG24: =0.76*POWER(S24,0.82) -> 3475.9139
C25: Diatoms, marine | D25: Menden-Deuer & Lessard 2000 | E25: L in µm; W in µm, V in µm3; CW(pg)= 0.288*V(µm3)0.811 | F25: no shape specified | G25: ' | H25: =X25 -> 1.2008102e-09 | I25: =X25/S25*POWER(10,15) -> 41.280814 | J25: in µm3 (=fL) | K25: µm | L25: µm | M25: na | N25: na | Q25: 50 | R25: =Q25/3 -> 16.666667 | S25: =4/3*PI()*(Q25/2)*POWER(R25,2) -> 29088.821 | T25: =((Q25*(POWER(R25,2))*PI())/6)/1000000 -> 0.0072722052 | U25: na | V25: na | W25: =AG25*POWER(10,-6) -> 0.0012008102 | X25: =W25/1000000 -> 1.2008102e-09 | Z25: length, width in µm | AB25: na | AG25: =0.288*POWER(S25,0.811) -> 1200.8102
C26: Protists - planktonic heterotrophic protists marine | D26: Pernice et al. 2016 and Menden-Deuer & Lessard 2000 | E26: L in µm; W in µm, V in µm3; CW(pg) = 0.21*V(µm3)0.939 | F26: prolate spheroid | G26: ' | H26: =X26 -> 3.3565458e-09 | I26: =X26/S26*POWER(10,15) -> 115.38954 | J26: in µm3 (=fL) | K26: µm | L26: µm | M26: na | N26: na | Q26: 50 | R26: =Q26/3 -> 16.666667 | S26: =4/3*PI()*(Q26/2)*POWER(R26,2) -> 29088.821 | T26: =((Q26*(POWER(R26,2))*PI())/6)/1000000 -> 0.0072722052 | U26: na | V26: na | W26: =AG26*POWER(10,-6) -> 0.0033565458 | X26: =W26/1000000 -> 3.3565458e-09 | Z26: length, width in µm | AB26: a | AG26: =0.216*POWER(S26,0.939) -> 3356.5458
C27: Tintinnid ciliates | D27: Verity and Lagdon 1984 | E27: na | F27: na | G27: ' | H27: =X27 -> na | I27: na | J27: na | K27: na | L27: na | M27: na | N27: na | Q27: na | R27: na | S27: na | T27: na | U27: na | V27: na | W27: na | X27: na | Z27: na | AB27: na
C28: Oligotrich ciliates | D28: Putt & Stoecker 1989 | E28: L in µm; W in µm, V in µm3; CW (pg) = 0.19*V(µm3) for cells preserved in Lugol. | F28: no shape specified | G28: ' | H28: =X28 -> 5.526876e-09 | I28: =X28/S28*POWER(10,15) -> 190 | K28: µm | L28: µm | M28: na | N28: na | Q28: 50 | R28: =Q28/3 -> 16.666667 | S28: =4/3*PI()*(Q28/2)*POWER(R28,2) -> 29088.821 | T28: =((Q28*(POWER(R28,2))*PI())/6)/1000000 -> 0.0072722052 | U28: a | V28: na | W28: =AG28*POWER(10,-6) -> 0.005526876 | X28: =W28/1000000 -> 5.526876e-09 | AB28: a | AG28: =S28*0.19 -> 5526.876
C29: Tetrahymena elliotti | D29: Gates et al. 1982 | E29: DW is 59% of WW | F29: prolate spheroid | G29: ' | H29: na | I29: na | K29: µm | L29: µm | M29: na | N29: na | Q29: 50 | R29: =Q29/3 -> 16.666667 | S29: =4/3*PI()*(Q29/2)*POWER(R29,2) -> 29088.821 | T29: =((Q29*(POWER(R29,2))*PI())/6)/1000000 -> 0.0072722052 | U29: =T29*1 -> 0.0072722052 | V29: =U29*0.59 -> 0.0042906011
C30: 14 marine ciliates | D30: Fenchel 1967 | E30: L in µm, WW in g, ρ=1, length-weight regressions for 14 species | F30: na
C31: Testate amoebae and ciliates in freshwater (river and moss) | D31: Schoenborn 1978 | E31: ρ=1 | F31: ellipsoid or cylinder
C32: Overestimation with exaggerated shape made out of carbon | F32: perfect sphere | G32: Sphere 50µm long | H32: =X32 -> 1.5998851e-08 | I32: =X32/S32*POWER(10,15) -> 550 | N32: 2.2 | Q32: 50 | R32: =Q32/3 -> 16.666667 | S32: =4/3*PI()*(Q32/2)*POWER(R32,2) -> 29088.821 | T32: =((Q32*(POWER(R32,2))*PI())/6)/1000000 -> 0.0072722052 | U32: =T32*N32 -> 0.015998851 | X32: =U32/POWER(10,6) -> 1.5998851e-08
C33: Micro-metazoans
C34: Micro-metazoan with prolate spheroid shape | D34: Reiss and Schmid-Araya 2010 | E34: L in µm; W in µm, V in µm3; ρ =1.1; FW = V*d, DW is 25% of FW, CW is 40% of DW. | F34: prolate spheroid | G34: 500 | H34: =X34 -> 7.9994257e-07 | I34: =X34/S34*POWER(10,15) -> 27.5 | J34: in µm3 (=fL) | K34: µm | L34: µm | M34: na | N34: na | Q34: 500 | R34: =Q34/3 -> 166.66667 | S34: =4/3*PI()*(Q34/2)*POWER(R34,2) -> 29088821 | T34: =((Q34*(POWER(R34,2))*PI())/6)/1000000 -> 7.2722052 | U34: =T34*1.1 -> 7.9994257 | V34: =U34*0.25 -> 1.9998564 | W34: =V34*0.4 -> 0.79994257 | X34: =W34/1000000 -> 7.9994257e-07 | Z34: length, width in µm | AB34: na
C35: Acari | D35: Feller & Warwick 1988 | E35: L in mm; W in mm; V in nL; V(nL) = a*b²*399; ρ =1.13; FW = V*d, DW is 25% of FW, CW is 40% of DW. | F35: no shape specified | G35: ' | H35: =X35 -> 6.2620833e-07 | I35: na | J35: V (nl) = a*b²*399 | K35: µm | L35: µm | M35: na | N35: na | Q35: 500 | R35: =Q35/3 -> 166.66667 | S35: na | T35: =Q35/1000*POWER(R35/1000,2)*399 -> 5.5416667 | U35: =T35*1.13 -> 6.2620833 | V35: =U35*0.25 -> 1.5655208 | W35: =V35*0.4 -> 0.62620833 | X35: =W35/1000000 -> 6.2620833e-07 | Z35: total length in mm | AB35: na
C36: Annelida - Oligochaeta | D36: Feller & Warwick 1988 | E36: L in mm; W in mm; V in nL; V(nL) = a*b²*530; ρ =1.13; FW = V*d, DW is 25% of FW, CW is 40% of DW. | F36: no shape specified | G36: ' | H36: =X36 -> 8.3180556e-07 | I36: na | J36: V (nl) = a*b²*530 | K36: µm | L36: µm | M36: na | N36: na | Q36: 500 | R36: =Q36/3 -> 166.66667 | S36: na | T36: =Q36/1000*POWER(R36/1000,2)*530 -> 7.3611111 | U36: =T36*1.13 -> 8.3180556 | V36: =U36*0.25 -> 2.0795139 | W36: =V36*0.4 -> 0.83180556 | X36: =W36/1000000 -> 8.3180556e-07 | Z36: total length in mm | AB36: na
C37: Crustacea - pyriform Cyclopoids | D37: Feller & Warwick 1988 | E37: L in mm; W in mm; V in nL; V(nL) = a*b²*400; ρ =1.13; FW = V*d, DW is 25% of FW, CW is 40% of DW. | F37: no shape specified | G37: ' | H37: =X37 -> 6.2777778e-07 | I37: na | J37: V (nl) = a*b²*400 | K37: µm | L37: µm | M37: na | N37: na | Q37: 500 | R37: =Q37/3 -> 166.66667 | S37: na | T37: =Q37/1000*POWER(R37/1000,2)*400 -> 5.5555556 | U37: =T37*1.13 -> 6.2777778 | V37: =U37*0.25 -> 1.5694444 | W37: =V37*0.4 -> 0.62777778 | X37: =W37/1000000 -> 6.2777778e-07 | Z37: total length in mm | AB37: na
C38: Crustacea - copepods -Calanoids | D38: Chisholm & Roff 1990 | E38: L in µm of prosome; DW in µg; lnDW (µg)=2.74lnL(µm)-16.41 | F38: no shape specified | G38: ' | H38: =X38 -> na | I38: na | J38: na | K38: µm | L38: µm | M38: na | N38: na | Q38: =Q37*2/3 -> 333.33333 | R38: na | S38: na | T38: na | U38: na | V38: =POWER(10,(2.74*LN(Q38)-16.41)) -> 0.32140438 | W38: na | X38: na | Z38: prosome length only, in µm | AB38: na | AE38: POWER(10,(2.74*LN(length in microm)-16.41))
C39: Crustacea - copepods -Cyclopoids | D39: Chisholm & Roff 1990 | E39: L in µm of prosome; DW in µg; lnDW (µg)=1.96lnL(µm)-11.64 | F39: no shape specified | G39: ' | H39: =X39 -> na | I39: na | J39: na | K39: µm | L39: µm | M39: na | N39: na | Q39: =Q38*2/3 -> 222.22222 | R39: na | S39: na | T39: na | U39: na | V39: =POWER(10,(1.96*LN(Q39)-11.64)) -> 0.089373476 | W39: na | X39: na | Z39: prosome length only, in µm | AB39: na | AE39: POWER(10,(1.96*LN(length in microm)-11.64))
C40: Crustacea - Ostracoda | D40: Feller & Warwick 1988 | E40: L in mm; W in mm; V in nL; V(nL) = a*b²*450; ρ =1.13; FW = V*d, DW is 25% of FW, CW is 40% of DW. | F40: no shape specified | G40: ' | H40: =X40 -> 7.0625e-07 | I40: na | J40: V (nl) = a*b²*450 | K40: µm | L40: µm | M40: na | N40: na | Q40: 500 | R40: =Q40/3 -> 166.66667 | S40: na | T40: =Q40/1000*POWER(R40/1000,2)*450 -> 6.25 | U40: =T40*1.13 -> 7.0625 | V40: =U40*0.25 -> 1.765625 | W40: =V40*0.4 -> 0.70625 | X40: =W40/1000000 -> 7.0625e-07 | Z40: total length in mm | AB40: na
...

Sheet 6
A1: Worked example for Methods alloemtric scaling correcting for temperature following Gillooly et al. 2001; the biological rate a1 at temperature T1 can be related to its value a2 at some other temperature T2; a2(T2)= a1(T1)e-(E/k)((1/T2)-(1/T1))
B4: Example - temperature corrected rate in bold
B6: Temperature 1 degree C | C6: 20
B7: Temperature 2 degree C | C7: 30
B8: Temperature 1 Kelvin | C8: =C6+273.15 -> 293.15
B9: Temperature 2 Kelvin | C9: =C7+273.15 -> 303.15
B10: e (Euler) | C10: 2.7182818
B11: k (Bolzmann's constant) in eV per Kelvin | C11: 8.617343e-05
B12: Ei (Activation energy metabolic rate) in eV | C12: 0.63
B13: Rate 1 at T1 | C13: 0.0845
B14: Rate 2 at T2 | C14: =C13*POWER(C10,(-(C12/C11)*((1/C9)-(1/C8)))) -> 0.19236801
A17: Calculations after Gillooly et al. 2001, equation 3
A18: Metabolic rate and its proxies can be ‘temperature corrected’ using equation given by Gillooly et al. (2002). Used by these authors for any biological rate (a) related to metabolism, this equation describes the temperature dependence of a. For example, a could be the intrinsic rate of population increase (r).
A19: After Gillooly et al. (2002), the biological rate a1 at temperature T1 can be related to its value a2 at some other temperature T2 by
A20: a2(T2)= a1(T1)e-(E/k)((1/T2)-(1/T1)),
A21: where e= Euler’s number, E =activation energy in eV, k=Bolzman constant (8.62*10-5 eV K‑1).
A22: Following Brown et al. (2004), activation energy can be assumed to be 0.63 eV, which is the average value for metabolic reactions according to these authors.
A23: In simple terms, on log-log scales, this equation predicts the intercept (which changes with temperature) of the log body mass-log intrinsic rate of population increase relationship while assuming that the slope of the relationship remains unchanged. These corrections should be used with caution as body mass can change — acutely or through evolution/adaptation — because of temperature. Also, many species have an optimal temperature range in which they operate.
AA38: Katrin Layer data unpubl.

Sheet 7
A1: Using Q10 to temperature correct; The Q10 coefficient is defined as the factor by which the rate of a reaction increases for every 10degree C rise in temperature
B4: Q10=Power((rate2 / rate1);(10/(T2-T1)))
B5: R2 = R1 * Power(Q10; ((T2-T1)/10))
B6: Example - temperature corrected rate in bold
B7: Q10 value | C7: 2
B8: Temperature 1 degree C | C8: 20
B9: Rate 1 at T1 | C9: 0.0845
B10: Temperature 2 degree C | C10: 30
B11: Rate 2 at T2 | C11: =C9*POWER(C7,((C10-C8)/10)) -> 0.169

Sheet 8 glossary
A1: Glossary
B2: Group | C2: Terminology and explanation
B3: Abbreviations | C3: L = length
C4: D = width
C5: V = volume
C6: FW = freshweight and wet weight (WW)
C7: DW = dryweight
C8: CW = carbon weight
C9: C = carbon
B10: Units | C10: 1 Ångstrom = 0.1nm
C11: Energy in watts: 1 Watt is equal to 1 joule per second
C12: Energy in joules: one joule corresponds to one kilogram-square metre per square second (1 J = 1 kg⋅m2⋅s−2).
C13: eV
C14: Dalton. 1 D = 1.6605*10-24 g
B15: Terminology | C15: Avogadro's number: The number 6.022 × 10²³ is known as Avogadro's number or Avogadro's constant. The concept of the mole can be used to convert between mass and number of particles
C16: Biomass abundaunce *body weight
C17: Production (the turnover of biomass over time)
C18: Metabolic rate, the rate of energy transformation within an organism
C19: Kleiber’s law - metabolic rate of all organisms scales with body mass as an exponent of ~0.75
C20: Euler’s number
C21: Boltzman constant
C22: Activation energy
C23: energetic equivalence rule: all size classes included in the analysis use the same amount of energy (energetic equivalence rule: Damuth 1987
C24: Microzooplankton can be defined either taxonomicallyas a diverse grouping of heterotrophic protists, or operationallyas a size class, typically <200 mm (Buitenhuis et al., 2010)
C25: Mesozooplankton are not only comprised of groups such as meroplanktonic larvae and copepods but also giant protists from the group Rhizaria (Hatton et al 2021)
C26: Molecular weight: The sum of the atomic masses of all atoms in a molecule, measured in dalton
AA49: Katrin Layer data unpubl.

Sheet 9 fig. 1
A1: Data used to create figure 1
B2: group | C2: group no | D2: x value | E2: carbon weight in g | F2: Y-axis | G2: length in m | H2: Y-axis | I2: weight pre-fix | J2: length pre-fix | K2: Ref carbon weight | L2: Ref length
B3: viruses | C3: 5 | D3: min | E3: 1e-17 | F3: 11 | G3: =16/1000/1000/1000 -> 1.6e-08 | H3: 7 | I3: attogram | J3: nanometre | K3: Bar-On et al., 2018 | L3: Modrow et al., 2013
B4: viruses | C4: 5 | D4: max | E4: 1e-15 | F4: 11 | G4: =300/1000/1000/1000 -> 3e-07 | H4: 7 | I4: femtogram | J4: nanometre | K4: na, conservative estimate from WW (Hatton et al. 2021) | L4: Modrow et al., 2013
B5: bacteria | C5: 4 | D5: min | E5: 5e-15 | F5: 10 | G5: 2e-07 | H5: 6 | I5: femtogram | J5: nanometre | K5: Whitman et al. 1998 | L5: Hatton et al. 2021
B6: bacteria | C6: 4 | D6: max | E6: =0.000000000001177/2 -> 5.885e-13 | F6: 10 | G6: 0.0001 | H6: 6 | I6: femtogram | J6: micrometre | K6: Loferer-Krossbacher et al. 1998 | L6: Head et al., 1996
B7: protists | C7: 3 | D7: min | E7: 1.4398966e-11 | F7: 5 | G7: =15/1000/1000 -> 1.5e-05 | H7: 4 | I7: femtogram | J7: micrometre | L7: Boenigk & Arndt, 2002
B8: protists | C8: 3 | D8: max | E8: 2.5918139e-06 | F8: 5 | G8: =2000/1000/1000 -> 0.002 | H8: 4 | I8: microgram | J8: millimetre | L8: Foissner & Berger, 1996
B9: micro-eukaryotes | C9: 2 | D9: min | E9: 1e-09 | F9: 3 | G9: =64/1000/1000 -> 6.4e-05 | H9: 3 | I9: femtogram | J9: micrometre | K9: Reiss & Schmid-Araya unpublished data | L9: Reiss & Schmid-Araya unpublished data
B10: micro-eukaryotes | C10: 2 | D10: max | E10: 1e-05 | F10: 3 | G10: =3/1000 -> 0.003 | H10: 3 | I10: microgram | J10: millimetre | K10: Reiss & Schmid-Araya unpublished data | L10: Reiss & Schmid-Araya unpublished data
B11: macrofauna | C11: 1 | D11: min | E11: 1.5e-07 | F11: 9 | G11: =2/1000 -> 0.002 | H11: 6 | I11: microgram | J11: millimetre | K11: Bar-On et al., 2018 | L11: Reiss et al. 2011
B12: macrofauna | C12: 1 | D12: max | E12: 1 | F12: 9 | G12: 0.2 | H12: 6 | I12: gram | J12: cm | K12: na, conservative estimate from WW (Hatton et al. 2021) | L12: Colombet et al., 2020
B13: milligram | C13: na | D13: min | E13: 1 | F13: 1 | G13: na
B14: milligram | C14: na | D14: max | E14: =POWER(10,-3) -> 0.001 | F14: 1 | G14: na
B15: microgram | C15: na | D15: min | E15: =POWER(10,-3) -> 0.001 | F15: 1 | G15: na
B16: microgram | C16: na | D16: max | E16: =POWER(10,-6) -> 1e-06 | F16: 1 | G16: na
B17: nanogram | C17: na | D17: min | E17: =POWER(10,-6) -> 1e-06 | F17: 1 | G17: na
B18: nanogram | C18: na | D18: max | E18: =POWER(10,-9) -> 1e-09 | F18: 1 | G18: na
B19: picogram | C19: na | D19: min | E19: =POWER(10,-9) -> 1e-09 | F19: 1 | G19: na
B20: picogram | C20: na | D20: max | E20: =POWER(10,-12) -> 1e-12 | F20: 1 | G20: na
B21: femtogram | C21: na | D21: min | E21: =POWER(10,-12) -> 1e-12 | F21: 1 | G21: na
B22: femtogram | C22: na | D22: max | E22: =POWER(10,-15) -> 1e-15 | F22: 1 | G22: na
B23: attogram | C23: na | D23: min | E23: =POWER(10,-15) -> 1e-15 | F23: 1 | G23: na
B24: attogram | C24: na | D24: max | E24: =POWER(10,-18) -> 1e-18 | F24: 1 | G24: na
B25: centimetre | C25: na | D25: min | E25: na | G25: 1 | H25: 1
B26: centimetre | C26: na | D26: max | E26: na | G26: =POWER(10,-2) -> 0.01 | H26: 1
B27: millimetre | C27: na | D27: min | E27: na | G27: =POWER(10,-2) -> 0.01 | H27: 1
B28: millimetre | C28: na | D28: max | E28: na | G28: =POWER(10,-3) -> 0.001 | H28: 1
B29: micrometre | C29: na | D29: min | E29: na | G29: =POWER(10,-3) -> 0.001 | H29: 1
B30: micrometre | C30: na | D30: max | E30: na | G30: =POWER(10,-6) -> 1e-06 | H30: 1
B31: nanometre | C31: na | D31: min | E31: na | G31: =POWER(10,-6) -> 1e-06 | H31: 1
B32: nanometre | C32: na | D32: max | E32: na | G32: =POWER(10,-9) -> 1e-09 | H32: 1
Y38: Katrin Layer data unpubl.

Sheet 10_Dan
A1: Group | B1: Min body mass | C1: Max body mass | D1: metabolism.b | E1: growth.b | F1: abundance.b | G1: biomass.b | H1: production.b | I1: Who
A2: Prokaryotes | B2: 5e-15 | C2: =0.000000000001177/2 -> 5.885e-13 | D2: 1.96 | E2: 0.73 | F2: na | G2: na | H2: -0.23 | I2: DeLong
A3: Protists | B3: 1.4398966e-11 | C3: 2.5918139e-06 | D3: 1.06 | E3: -0.26 | F3: na | G3: na | H3: -0.32 | I3: DeLong
A4: Micro-metazoans | B4: 1e-09 | C4: 1e-05 | D4: 0.79 | E4: -0.23 | F4: na | G4: na | H4: -0.02 | I4: DeLong
A5: Prokaryotes | B5: 5e-15 | C5: 5.885e-13 | D5: 2 | E5: 0.75 | F5: -2 | G5: -1 | H5: -0.25 | I5: Theory
A6: Protists | B6: 1.4398966e-11 | C6: 2.5918139e-06 | D6: 1 | E6: -0.25 | F6: -1 | G6: 0 | H6: -0.25 | I6: Theory
A7: Micro-metazoans | B7: 1e-09 | C7: 1e-05 | D7: 0.75 | E7: -0.25 | F7: -0.75 | G7: 0.25 | H7: 0 | I7: Theory

Sheet 10 fig. 2
A1: Methods allometric scaling | B1: Approach | C1: Group | D1: size | E1: Body mass | F1: logM | G1: log W | H1: logRmax | I1: logN | J1: logB | K1: log P | L1: log P/B | M1: empty | N1: exp. M-W after deLong | O1: exp. M-R max | P1: exp. M-N | Q1: exp. M-B | R1: exp. M-P | S1: exp. M-W after deLong | T1: Metabolic rate | U1: Rmax | V1: Abundance | W1: Biomass | X1: Production | Y1: P/B | Z1: empty3 | AA1: ReferenceM_N | AC1: Reference_metabolic rate | AD1: Reference_Rmax | AE1: ReferenceN | AF1: ReferenceB | AG1: ReferenceP | AH1: ReferenceP/B
A2: ignore intercept here- these are just dummy dat to show the theoretical intercept | B2: Theory | C2: Prokaryotes | D2: small | E2: ='9 fig. 1'!E$3 -> 1e-17 | F2: =LOG(E2) -> -17 | G2: =N2*$F2 -> -34 | H2: =O2*$F2 -> -12.75 | I2: =P2*$F2 -> 34 | J2: =LOG(W2) -> 17 | K2: =LOG(X2) -> 4.25 | L2: =LOG(Y2) -> -12.75 | N2: 2 | O2: 0.75 | P2: =-N2 -> -2 | Q2: =SLOPE(J2:J3,F2:F3) -> -1 | R2: =SLOPE(K2:K3,F2:F3) -> -0.25 | S2: -0.5 | T2: =POWER(10,G2) -> 1e-34 | U2: =POWER(10,H2) -> 1.7782794e-13 | V2: =POWER(10,I2) -> 1e+34 | W2: =V2*E2 -> 1e+17 | X2: =W2*U2 -> 17782.794 | Y2: =X2/W2 -> 1.7782794e-13 | AA2: reciprocal of metabolic rate | AC2: DeLong | AD2: DeLong | AF2: N*body mass | AG2: Biomass*Rmax | AH2: P over B
B3: Theory | C3: Prokaryotes | D3: large | E3: ='9 fig. 1'!E$6 -> 5.885e-13 | F3: =LOG(E3) -> -12.230254 | G3: =N3*$F3 -> -24.460507 | H3: =O3*$F3 -> -9.1726901 | I3: =P3*$F3 -> 24.460507 | J3: =LOG(W3) -> 12.230254 | K3: =LOG(X3) -> 3.0575634 | L3: =LOG(Y3) -> -9.1726901 | N3: 2 | O3: 0.75 | P3: =-N3 -> -2 | Q3: =SLOPE(J2:J3,F2:F3) -> -1 | R3: =SLOPE(K2:K3,F2:F3) -> -0.25 | S3: -0.5 | T3: =POWER(10,G3) -> 3.4633225e-25 | U3: =POWER(10,H3) -> 6.7190806e-10 | V3: =POWER(10,I3) -> 2.8874008e+24 | W3: =V3*E3 -> 1.6992353e+12 | X3: =W3*U3 -> 1141.7299 | Y3: =X3/W3 -> 6.7190806e-10 | AA3: reciprocal of metabolic rate | AC3: DeLong | AD3: DeLong | AF3: N*body mass | AG3: Biomass*Rmax | AH3: P over B
B4: Theory | C4: Eukaryotes protists | D4: small | E4: ='9 fig. 1'!E$7 -> 1.4398966e-11 | F4: =LOG(E4) -> -10.841669 | G4: =N4*$F4 -> -10.841669 | H4: =O4*$F4 -> 2.7104172 | I4: =P4*$F4 -> 10.841669 | J4: =LOG(W4) -> 8.6789472e-16 | K4: =LOG(X4) -> 2.7104172 | L4: =LOG(Y4) -> 2.7104172 | N4: 1 | O4: -0.25 | P4: =-N4 -> -1 | Q4: =SLOPE(J4:J5,F4:F5) -> 3.6699428e-17 | R4: =SLOPE(K4:K5,F4:F5) -> -0.25 | S4: -1.5 | T4: =POWER(10,G4) -> 1.4398966e-11 | U4: =POWER(10,H4) -> 513.35426 | V4: =POWER(10,I4) -> 6.944943e+10 | W4: =V4*E4 -> 1 | X4: =W4*U4 -> 513.35426 | Y4: =X4/W4 -> 513.35426 | AA4: reciprocal of metabolic rate | AC4: DeLong | AD4: DeLong | AF4: N*body mass | AG4: Biomass*Rmax | AH4: P over B
B5: Theory | C5: Eukaryotes protists | D5: large | E5: ='9 fig. 1'!E$8 -> 2.5918139e-06 | F5: =LOG(E5) -> -5.5863962 | G5: =N5*$F5 -> -5.5863962 | H5: =O5*$F5 -> 1.396599 | I5: =P5*$F5 -> 5.5863962 | J5: =LOG(W5) -> 1.0607602e-15 | K5: =LOG(X5) -> 1.396599 | L5: =LOG(Y5) -> 1.396599 | N5: 1 | O5: -0.25 | P5: =-N5 -> -1 | Q5: =SLOPE(J4:J5,F4:F5) -> 3.6699428e-17 | R5: =SLOPE(K4:K5,F4:F5) -> -0.25 | S5: -1.5 | T5: =POWER(10,G5) -> 2.5918139e-06 | U5: =POWER(10,H5) -> 24.922927 | V5: =POWER(10,I5) -> 385830.17 | W5: =V5*E5 -> 1 | X5: =W5*U5 -> 24.922927 | Y5: =X5/W5 -> 24.922927 | AA5: reciprocal of metabolic rate | AC5: DeLong | AD5: DeLong | AF5: N*body mass | AG5: Biomass*Rmax | AH5: P over B
B6: Theory | C6: Micro-Eukaryotes non protist | D6: small | E6: ='9 fig. 1'!E$9 -> 1e-09 | F6: =LOG(E6) -> -9 | G6: =N6*$F6 -> -6.75 | H6: =O6*$F6 -> 2.25 | I6: =P6*$F6 -> 6.75 | J6: =LOG(W6) -> -2.25 | K6: =LOG(X6) -> 8.6789472e-16 | L6: =LOG(Y6) -> 2.25 | N6: 0.75 | O6: -0.25 | P6: =-N6 -> -0.75 | Q6: =SLOPE(J6:J7,F6:F7) -> 0.25 | R6: =SLOPE(K6:K7,F6:F7) -> 0 | S6: -1.25 | T6: =POWER(10,G6) -> 1.7782794e-07 | U6: =POWER(10,H6) -> 177.82794 | V6: =POWER(10,I6) -> 5623413.3 | W6: =V6*E6 -> 0.0056234133 | X6: =W6*U6 -> 1 | Y6: =X6/W6 -> 177.82794 | AA6: reciprocal of metabolic rate | AC6: DeLong | AD6: DeLong | AE6: Brown et al. 2004 | AF6: Brown et al. 2004 | AG6: Biomass*Rmax | AH6: P over B
B7: Theory | C7: Micro-Eukaryotes non protist | D7: large | E7: ='9 fig. 1'!E$10 -> 1e-05 | F7: =LOG(E7) -> -5 | G7: =N7*$F7 -> -3.75 | H7: =O7*$F7 -> 1.25 | I7: =P7*$F7 -> 3.75 | J7: =LOG(W7) -> -1.25 | K7: =LOG(X7) -> 8.6789472e-16 | L7: =LOG(Y7) -> 1.25 | N7: 0.75 | O7: -0.25 | P7: =-N7 -> -0.75 | Q7: =SLOPE(J6:J7,F6:F7) -> 0.25 | R7: =SLOPE(K6:K7,F6:F7) -> 0 | S7: -1.25 | T7: =POWER(10,G7) -> 0.00017782794 | U7: =POWER(10,H7) -> 17.782794 | V7: =POWER(10,I7) -> 5623.4133 | W7: =V7*E7 -> 0.056234133 | X7: =W7*U7 -> 1 | Y7: =X7/W7 -> 17.782794 | AA7: reciprocal of metabolic rate | AC7: DeLong | AD7: DeLong | AE7: Brown et al. 2004 | AF7: Brown et al. 2004 | AG7: Biomass*Rmax | AH7: P over B
B8: Theory | C8: macroeukaryotes | D8: small | E8: ='9 fig. 1'!E$11 -> 1.5e-07 | F8: =LOG(E8) -> -6.8239087 | G8: =N8*$F8 -> -5.1179316 | H8: =O8*$F8 -> 1.7059772 | I8: =P8*$F8 -> 5.1179316 | J8: =LOG(W8) -> -1.7059772 | K8: =LOG(X8) -> 5.7859648e-16 | L8: =LOG(Y8) -> 1.7059772 | N8: 0.75 | O8: -0.25 | P8: =-N8 -> -0.75 | Q8: =SLOPE(J8:J9,F8:F9) -> 0.25 | R8: =SLOPE(K8:K9,F8:F9) -> -8.4789598e-17 | S8: -1.25 | T8: =POWER(10,G8) -> 7.6219912e-06 | U8: =POWER(10,H8) -> 50.813275 | V8: =POWER(10,I8) -> 131199.31 | W8: =V8*E8 -> 0.019679897 | X8: =W8*U8 -> 1 | Y8: =X8/W8 -> 50.813275 | AA8: reciprocal of metabolic rate | AC8: DeLong | AD8: DeLong | AE8: Brown et al. 2004 | AF8: Brown et al. 2004 | AG8: Biomass*Rmax | AH8: P over B
B9: Theory | C9: macroeukaryotes | D9: large | E9: ='9 fig. 1'!E$12 -> 1 | F9: =LOG(E9) -> 0 | G9: =N9*$F9 -> 0 | H9: =O9*$F9 -> 0 | I9: =P9*$F9 -> 0 | J9: =LOG(W9) -> 0 | K9: =LOG(X9) -> 0 | L9: =LOG(Y9) -> 0 | N9: 0.75 | O9: -0.25 | P9: =-N9 -> -0.75 | Q9: =SLOPE(J8:J9,F8:F9) -> 0.25 | R9: =SLOPE(K8:K9,F8:F9) -> -8.4789598e-17 | S9: -1.25 | T9: =POWER(10,G9) -> 1 | U9: =POWER(10,H9) -> 1 | V9: =POWER(10,I9) -> 1 | W9: =V9*E9 -> 1 | X9: =W9*U9 -> 1 | Y9: =X9/W9 -> 1 | AA9: reciprocal of metabolic rate | AC9: DeLong | AD9: DeLong | AE9: Brown et al. 2004 | AF9: Brown et al. 2004 | AG9: Biomass*Rmax | AH9: P over B
B10: Theory | C10: Across all groups | D10: small | E10: =E$2 -> 1e-17 | F10: =LOG(E10) -> -17 | G10: =N10*$F10 -> -12.75 | H10: =O10*$F10 -> 4.25 | I10: =P10*$F10 -> 12.75 | J10: =LOG(W10) -> -4.25 | K10: =LOG(X10) -> 1.2536257e-15 | L10: =LOG(Y10) -> 4.25 | N10: 0.75 | O10: -0.25 | P10: =-N10 -> -0.75 | Q10: =SLOPE(J10:J11,F10:F11) -> 0.25 | R10: =SLOPE(K10:K11,F10:F11) -> -7.3742689e-17 | S10: -1.25 | T10: =POWER(10,G10) -> 1.7782794e-13 | U10: =POWER(10,H10) -> 17782.794 | V10: =POWER(10,I10) -> 5.6234133e+12 | W10: =V10*E10 -> 5.6234133e-05 | X10: =W10*U10 -> 1 | Y10: =X10/W10 -> 17782.794 | AA10: reciprocal of metabolic rate | AC10: DeLong | AD10: DeLong | AE10: Brown et al. 2004 | AF10: Brown et al. 2004 | AG10: Biomass*Rmax | AH10: P over B
B11: Theory | C11: Across all groups | D11: large | E11: =E$9 -> 1 | F11: =LOG(E11) -> 0 | G11: =N11*$F11 -> 0 | H11: =O11*$F11 -> 0 | I11: =P11*$F11 -> 0 | J11: =LOG(W11) -> 0 | K11: =LOG(X11) -> 0 | L11: =LOG(Y11) -> 0 | N11: 0.75 | O11: -0.25 | P11: =-N11 -> -0.75 | Q11: =SLOPE(J10:J11,F10:F11) -> 0.25 | R11: =SLOPE(K10:K11,F10:F11) -> -7.3742689e-17 | S11: -1.25 | T11: =POWER(10,G11) -> 1 | U11: =POWER(10,H11) -> 1 | V11: =POWER(10,I11) -> 1 | W11: =V11*E11 -> 1 | X11: =W11*U11 -> 1 | Y11: =X11/W11 -> 1 | AA11: reciprocal of metabolic rate | AC11: DeLong | AD11: DeLong | AE11: Brown et al. 2004 | AF11: Brown et al. 2004 | AG11: Biomass*Rmax | AH11: P over B
A12: ignore intercept here- these are just dummy dat to show the theoretical intercept | B12: DeLong data | C12: Prokaryotes | D12: small | E12: ='9 fig. 1'!E$3 -> 1e-17 | F12: =LOG(E12) -> -17 | G12: =N12*$F12 -> -33.32 | H12: =O12*$F12 -> -12.41 | I12: =P12*$F12 -> 33.32 | J12: =LOG(W12) -> 16.32 | K12: =LOG(X12) -> 3.91 | L12: =LOG(Y12) -> -12.41 | N12: 1.96 | O12: 0.73 | P12: =-N12 -> -1.96 | Q12: =SLOPE(J12:J13,F12:F13) -> -0.96 | R12: =SLOPE(K12:K13,F12:F13) -> -0.23 | S12: -0.5 | T12: =POWER(10,G12) -> 4.7863009e-34 | U12: =POWER(10,H12) -> 3.8904514e-13 | V12: =POWER(10,I12) -> 2.0892961e+33 | W12: =V12*E12 -> 2.0892961e+16 | X12: =W12*U12 -> 8128.3052 | Y12: =X12/W12 -> 3.8904514e-13 | AA12: reciprocal of metabolic rate | AC12: DeLong | AD12: DeLong | AF12: N*body mass | AG12: Biomass*Rmax | AH12: P over B
B13: DeLong data | C13: Prokaryotes | D13: large | E13: ='9 fig. 1'!E$6 -> 5.885e-13 | F13: =LOG(E13) -> -12.230254 | G13: =N13*$F13 -> -23.971297 | H13: =O13*$F13 -> -8.9280851 | I13: =P13*$F13 -> 23.971297 | J13: =LOG(W13) -> 11.741043 | K13: =LOG(X13) -> 2.8129583 | L13: =LOG(Y13) -> -8.9280851 | N13: 1.96 | O13: 0.73 | P13: =-N13 -> -1.96 | Q13: =SLOPE(J12:J13,F12:F13) -> -0.96 | R13: =SLOPE(K12:K13,F12:F13) -> -0.23 | S13: -0.5 | T13: =POWER(10,G13) -> 1.0683242e-24 | U13: =POWER(10,H13) -> 1.1800894e-09 | V13: =POWER(10,I13) -> 9.3604542e+23 | W13: =V13*E13 -> 5.5086273e+11 | X13: =W13*U13 -> 650.06729 | Y13: =X13/W13 -> 1.1800894e-09 | AA13: reciprocal of metabolic rate | AC13: DeLong | AD13: DeLong | AF13: N*body mass | AG13: Biomass*Rmax | AH13: P over B
B14: DeLong data | C14: Eukaryotes protists | D14: small | E14: ='9 fig. 1'!E$7 -> 1.4398966e-11 | F14: =LOG(E14) -> -10.841669 | G14: =N14*$F14 -> -11.492169 | H14: =O14*$F14 -> 2.8188339 | I14: =P14*$F14 -> 11.492169 | J14: =LOG(W14) -> 0.65050012 | K14: =LOG(X14) -> 3.469334 | L14: =LOG(Y14) -> 2.8188339 | N14: 1.06 | O14: -0.26 | P14: =-N14 -> -1.06 | Q14: =SLOPE(J14:J15,F14:F15) -> -0.06 | R14: =SLOPE(K14:K15,F14:F15) -> -0.32 | S14: -1.58 | T14: =POWER(10,G14) -> 3.219817e-12 | U14: =POWER(10,H14) -> 658.92177 | V14: =POWER(10,I14) -> 3.1057665e+11 | W14: =V14*E14 -> 4.4719828 | X14: =W14*U14 -> 2946.6868 | Y14: =X14/W14 -> 658.92177 | AA14: reciprocal of metabolic rate | AC14: DeLong | AD14: DeLong | AF14: N*body mass | AG14: Biomass*Rmax | AH14: P over B
B15: DeLong data | C15: Eukaryotes protists | D15: large | E15: ='9 fig. 1'!E$8 -> 2.5918139e-06 | F15: =LOG(E15) -> -5.5863962 | G15: =N15*$F15 -> -5.9215799 | H15: =O15*$F15 -> 1.452463 | I15: =P15*$F15 -> 5.9215799 | J15: =LOG(W15) -> 0.33518377 | K15: =LOG(X15) -> 1.7876468 | L15: =LOG(Y15) -> 1.452463 | N15: 1.06 | O15: -0.26 | P15: =-N15 -> -1.06 | Q15: =SLOPE(J14:J15,F14:F15) -> -0.06 | R15: =SLOPE(K14:K15,F14:F15) -> -0.32 | S15: -1.58 | T15: =POWER(10,G15) -> 1.1978986e-06 | U15: =POWER(10,H15) -> 28.344122 | V15: =POWER(10,I15) -> 834795.21 | W15: =V15*E15 -> 2.1636339 | X15: =W15*U15 -> 61.326302 | Y15: =X15/W15 -> 28.344122 | AA15: reciprocal of metabolic rate | AC15: DeLong | AD15: DeLong | AF15: N*body mass | AG15: Biomass*Rmax | AH15: P over B
